<?xml version="1.0" ?>
<!-- =================================================================================== -->
<!-- |    This document was autogenerated by xacro from src/ground_agent/urdfs/agilex_sawyer.urdf.xacro | -->
<!-- |    EDITING THIS FILE BY HAND IS NOT RECOMMENDED                                 | -->
<!-- =================================================================================== -->
<robot name="agilex">
  <transmission name="front_left_wheel_trans">
    <type>transmission_interface/SimpleTransmission</type>
    <actuator name="front_left_wheel_motor">
      <mechanicalReduction>1</mechanicalReduction>
    </actuator>
    <joint name="front_left_wheel">
      <hardwareInterface>hardware_interface/VelocityJointInterface</hardwareInterface>
    </joint>
  </transmission>
  <transmission name="rear_left_wheel_trans">
    <type>transmission_interface/SimpleTransmission</type>
    <actuator name="rear_left_wheel_motor">
      <mechanicalReduction>1</mechanicalReduction>
    </actuator>
    <joint name="rear_left_wheel">
      <hardwareInterface>hardware_interface/VelocityJointInterface</hardwareInterface>
    </joint>
  </transmission>
  <transmission name="front_right_wheel_trans">
    <type>transmission_interface/SimpleTransmission</type>
    <actuator name="front_right_wheel_motor">
      <mechanicalReduction>1</mechanicalReduction>
    </actuator>
    <joint name="front_right_wheel">
      <hardwareInterface>hardware_interface/VelocityJointInterface</hardwareInterface>
    </joint>
  </transmission>
  <transmission name="rear_right_wheel_trans">
    <type>transmission_interface/SimpleTransmission</type>
    <actuator name="rear_right_wheel_motor">
      <mechanicalReduction>1</mechanicalReduction>
    </actuator>
    <joint name="rear_right_wheel">
      <hardwareInterface>hardware_interface/VelocityJointInterface</hardwareInterface>
    </joint>
  </transmission>
  
  <!-- Base link -->
  <link name="base_link">
    <visual>
      <origin rpy="0 0 0" xyz="0 0 0"/>
      <geometry>
        <mesh filename="model://agilex/meshes/base_link.dae"/>
      </geometry>
    </visual>
    <collision>
      <origin rpy="0 0 0" xyz="0 0 0.008"/>
      <geometry>
        <box size="0.925 0.38 0.21"/>
      </geometry>
    </collision>
    <collision>
      <origin rpy="0 0 0" xyz="0 0 0.034999999999999996"/>
      <geometry>
        <box size="0.15416666666666667 0.627 0.06999999999999999"/>
      </geometry>
    </collision>
  </link>
  <link name="base_footprint"/>
  <joint name="base_footprint_joint" type="fixed">
    <origin rpy="0 0 0" xyz="0 0 -0.23479"/>
    <parent link="base_link"/>
    <child link="base_footprint"/>
  </joint>
  <link name="inertial_link">
    <inertial>
      <mass value="40"/>
      <origin xyz="0.0 0.0 0.0"/>
      <inertia ixx="2.288641" ixy="0" ixz="0" iyy="5.103976" iyz="0" izz="3.431465"/>
    </inertial>
  </link>
  <joint name="inertial_joint" type="fixed">
    <origin rpy="0 0 0" xyz="0 0 0"/>
    <parent link="base_link"/>
    <child link="inertial_link"/>
  </joint>
  <link name="front_right_wheel_link">
    <inertial>
      <mass value="3"/>
      <origin xyz="0 0 0"/>
      <inertia ixx="0.7171" ixy="0" ixz="0" iyy="0.1361" iyz="0" izz="0.7171"/>
    </inertial>
    <visual>
      <origin rpy="0 0 0" xyz="0 0 0"/>
      <geometry>
        <!-- <cylinder length="${wheel_length}" radius="${wheel_radius}" /> -->
        <mesh filename="model://agilex/meshes/wheel_type1.dae"/>
      </geometry>
      <!-- <material>
                    <color rgba="0.2 0.2 0.2 1.0" />
                </material> -->
    </visual>
    <collision>
      <origin rpy="1.570795 0 0" xyz="0 0 0"/>
      <geometry>
        <cylinder length="0.11653" radius="0.16459"/>
      </geometry>
    </collision>
  </link>
  <joint name="front_right_wheel" type="revolute">
    <parent link="base_link"/>
    <child link="front_right_wheel_link"/>
    <origin rpy="0 0 0" xyz="0.249 -0.29153 -0.0702"/>
    <axis rpy="0 0 0" xyz="0 1 0"/>
    <limit effort="10000" lower="-100000" upper="100000" velocity="100"/>
    <dynamics damping="0.05" friction="0.0"/>
  </joint>
  <link name="front_left_wheel_link">
    <inertial>
      <mass value="3"/>
      <origin xyz="0 0 0"/>
      <inertia ixx="0.7171" ixy="0" ixz="0" iyy="0.1361" iyz="0" izz="0.7171"/>
    </inertial>
    <visual>
      <origin rpy="0 0 0" xyz="0 0 0"/>
      <geometry>
        <mesh filename="model://agilex/meshes/wheel_type2.dae"/>
        <!-- <cylinder length="${wheel_length}" radius="${wheel_radius}" /> -->
      </geometry>
      <!-- <material>
                    <color rgba="0.2 0.2 0.2 1.0" />
                </material> -->
    </visual>
    <collision>
      <origin rpy="1.570795 0 0" xyz="0 0 0"/>
      <geometry>
        <cylinder length="0.11653" radius="0.16459"/>
      </geometry>
    </collision>
  </link>
  <joint name="front_left_wheel" type="revolute">
    <parent link="base_link"/>
    <child link="front_left_wheel_link"/>
    <origin rpy="0 0 0" xyz="0.249 0.29153 -0.0702"/>
    <axis rpy="0 0 0" xyz="0 1 0"/>
    <limit effort="10000" lower="-100000" upper="100000" velocity="100"/>
    <dynamics damping="0.05" friction="0.0"/>
  </joint>
  <link name="rear_left_wheel_link">
    <inertial>
      <mass value="3"/>
      <origin xyz="0 0 0"/>
      <inertia ixx="0.7171" ixy="0" ixz="0" iyy="0.1361" iyz="0" izz="0.7171"/>
    </inertial>
    <visual>
      <origin rpy="0 0 0" xyz="0 0 0"/>
      <geometry>
        <!-- <cylinder length="${wheel_length}" radius="${wheel_radius}" /> -->
        <mesh filename="model://agilex/meshes/wheel_type1.dae"/>
      </geometry>
      <!-- <material>
                    <color rgba="0.2 0.2 0.2 1.0" />
                </material> -->
    </visual>
    <collision>
      <origin rpy="1.570795 0 0" xyz="0 0 0"/>
      <geometry>
        <cylinder length="0.11653" radius="0.16459"/>
      </geometry>
    </collision>
  </link>
  <joint name="rear_left_wheel" type="revolute">
    <parent link="base_link"/>
    <child link="rear_left_wheel_link"/>
    <origin rpy="0 0 0" xyz="-0.249 0.29153 -0.0702"/>
    <axis rpy="0 0 0" xyz="0 1 0"/>
    <limit effort="10000" lower="-100000" upper="100000" velocity="100"/>
    <dynamics damping="0.05" friction="0.0"/>
  </joint>
  <link name="rear_right_wheel_link">
    <inertial>
      <mass value="3"/>
      <origin xyz="0 0 0"/>
      <inertia ixx="0.7171" ixy="0" ixz="0" iyy="0.1361" iyz="0" izz="0.7171"/>
    </inertial>
    <visual>
      <origin rpy="0 0 0" xyz="0 0 0"/>
      <geometry>
        <mesh filename="model://agilex/meshes/wheel_type2.dae"/>
        <!-- <cylinder length="${wheel_length}" radius="${wheel_radius}" /> -->
      </geometry>
      <!-- <material>
                    <color rgba="0.2 0.2 0.2 1.0" />
                </material> -->
    </visual>
    <collision>
      <origin rpy="1.570795 0 0" xyz="0 0 0"/>
      <geometry>
        <cylinder length="0.11653" radius="0.16459"/>
      </geometry>
    </collision>
  </link>
  <joint name="rear_right_wheel" type="revolute">
    <parent link="base_link"/>
    <child link="rear_right_wheel_link"/>
    <origin rpy="0 0 0" xyz="-0.249 -0.29153 -0.0702"/>
    <axis rpy="0 0 0" xyz="0 1 0"/>
    <limit effort="10000" lower="-100000" upper="100000" velocity="100"/>
    <dynamics damping="0.05" friction="0.0"/>
  </joint>

  <!-- <link name="base_link_flip"/> -->

  <!-- 180-degree flip so “forward” points away from the cliff -->
  <!-- <joint name="base_link_flip_joint" type="fixed">
    <parent link="base_link_flip"/>
    <child  link="base_link"/>
     rotate π rad about Z 
    <origin xyz="0 0 0" rpy="0 0 3.1415926535"/>
  </joint> -->

 
  <!-- IMU Sensor as standalone model attached to base_link -->
  <link name="imu_link">
    <inertial>
      <mass value="0.01"/>
      <inertia ixx="1e-5" iyy="1e-5" izz="1e-5" ixy="0" ixz="0" iyz="0"/>
    </inertial>
    <collision>
      <geometry>
        <sphere radius="0.05"/>
      </geometry>
    </collision>

    <visual>
      <geometry>
        <sphere radius="0.05"/>
      </geometry>
      <material name="white" />
    </visual>

  </link>

  <joint name="imu_joint" type="fixed">
    <parent link="base_link"/>
    <child link="imu_link"/>
    <origin xyz="0 0 0.1" rpy="0 0 0"/>
  </joint>

  <gazebo reference="imu_link">
    <sensor name="GazeboIMU" type="imu">
        <always_on>1</always_on>
        <update_rate>100.0</update_rate>
        <visualize>true</visualize>
        <topic>agilex/imu/data</topic>
        <frame_id>agilex_diff_drive/base_link</frame_id>
        <ignition_frame_id>agilex_diff_drive/base_link</ignition_frame_id>
        <imu>
            <orientation_reference_frame>
                <localization>ENU</localization>
            </orientation_reference_frame>
        </imu>
    </sensor>
  </gazebo>
  
  <!-- agilex_diff_drive.urdf.xacro (excerpt) -->
<!-- … existing drivetrain links … -->

<!-- Lidar link rigidly attached to base_link -->
<link name="gpu_lidar">
  <inertial>
    <mass value="0.005"/>
    <inertia ixx="8.33e-06" iyy="8.33e-06" izz="8.33e-06" ixy="0" ixz="0" iyz="0"/>
  </inertial>
  <visual>
    <geometry><cylinder radius="0.03" length="0.01"/></geometry>
    <material name="black"/>
  </visual>
  <collision>
    <geometry><cylinder radius="0.03" length="0.01"/></geometry>
  </collision>
</link>

<joint name="gpu_lidar_joint" type="fixed">
  <parent link="base_link"/>
  <child  link="gpu_lidar"/>
  <!-- offset of the sensor relative to the robot base -->
  <origin xyz="0.50 0 1.80" rpy="0 0 0"/>
</joint>

<!-- Gazebo GPU-LIDAR sensor -->
<gazebo reference="gpu_lidar">
  <sensor name="gpu_lidar" type="gpu_lidar">
    <update_rate>10</update_rate>
    <pose>0 0 0 0 0 0</pose>

    <ray>
      <scan>
        <horizontal>
          <samples>720</samples>
          <min_angle>-1.5708</min_angle>
          <max_angle> 1.5708</max_angle>
        </horizontal>
      </scan>
      <range><min>0.1</min><max>10.0</max></range>
    </ray>

    <!-- Make Gazebo stamp LaserScan with 'gpu_lidar' -->
    <!-- <frame_name>agilex_diff_drive_gpu_lidar</frame_name> -->
    <!-- <frame_name>gpu_lidar</frame_name> -->
    <frame_name>agilex_diff_drive/base_link/gpu_lidar</frame_name>

    <topic>/scan</topic>
    <always_on>1</always_on>
    <visualize>true</visualize>
  </sensor>
   <!-- (2) Gazebo-ROS bridge for the lidar  -->
  <!--     Fortress uses libgazebo_ros_ray_sensor.so for 2-D lidars        -->
  <plugin name="gpu_laser_ros" filename="libgazebo_ros_ray_sensor.so">
    <!-- must match the TF frame you use everywhere else -->
    <frame_name>agilex_diff_drive/base_link/gpu_lidar</frame_name>

    <!-- ROS topic to publish -->
    <topicName>/scan</topicName>

    <!-- Pass ROS arguments (use_sim_time!) to the plugin -->
    <ros>
      <!-- you can add remaps / namespace here too -->
      <arguments>--ros-args -p use_sim_time:=true</arguments>
    </ros>
  </plugin>
</gazebo>


<!-- GNSS  -->
<link name="gnss_link">
  <collision>
    <geometry>
      <sphere radius="0.05"/>
    </geometry>
  </collision>
  <visual>
    <geometry>
      <sphere radius="0.05"/>
    </geometry>
    <material name="black" />
  </visual>
  <inertial>
    <origin xyz="0 0 0.1" rpy="0.3 1.6 -0.4"/>
    <mass value="0.005"/>
    <inertia ixx="0.1" ixy="0.0" ixz="0.0" iyy="0.1" iyz="0.0" izz="0.1"/>
  </inertial>
</link>

<joint name="gnss_joint" type="fixed">
  <origin xyz="0 0 -0.05" rpy="0 0 0"/>
  <parent link="base_link"/>
  <child link="gnss_link"/>
</joint>

  <gazebo reference="gnss_link">
      <sensor name="GazeboNavSat" type="navsat">
          <always_on>1</always_on>
          <update_rate>25.0</update_rate>
          <visualize>true</visualize>
          <topic>gps/fix</topic>
      </sensor>
  </gazebo>
  
  <!-- camera-->
  <link name="rgb_cam_link">
    <inertial>
      <origin xyz="0 0 0" rpy="0 0 0"/>
      <mass value="0.04"/>
      <inertia 
        ixx="2e-5" iyy="2e-5" izz="2e-5"
        ixy="0.0" ixz="0.0" iyz="0.0"/>
    </inertial>
    <visual>
      <origin xyz="0 0 0" rpy="0 0 0"/>
      <geometry>
        <box size="0.04 0.04 0.02"/>
      </geometry>
      <material name="black"/>
    </visual>
    <collision>
      <origin xyz="0 0 0" rpy="0 0 0"/>
      <geometry>
        <box size="0.04 0.04 0.02"/>
      </geometry>
    </collision>
  </link>

  <joint name="rgb_cam_joint" type="fixed">
    <parent link="base_link"/>
    <child  link="rgb_cam_link"/>
    <origin xyz="0.38 -0.24 0.15" rpy="0 0.18 -1.5708"/>
  </joint>

  <gazebo reference="rgb_cam_link">
    <sensor name="rgb_cam" type="camera">
      <update_rate>30</update_rate>
      <camera>
        <horizontal_fov>1.3962634</horizontal_fov> <!-- 80 deg -->
        <image>
          <width>1280</width>
          <height>720</height>
          <format>R8G8B8</format>
        </image>
        <clip>
          <near>0.05</near>
          <far>30.0</far>
        </clip>
      </camera>

      <!-- Gazebo ROS 2 camera bridge plugin -->
      <plugin name="rgb_ros_bridge" filename="libgazebo_ros_camera.so">
        <ros>
          <arguments>--ros-args -p use_sim_time:=true</arguments>
        </ros>
        <camera_name>rgb_cam</camera_name>
        <image_topic>/agilex_diff_drive/camera/color/image_raw</image_topic>
        <info_topic>/agilex_diff_drive/camera/color/camera_info</info_topic>
        <frame_name>agilex_diff_drive/rgb_cam_link</frame_name>
      </plugin>
    </sensor>
  </gazebo>
  

  <!-- === ros2_control Block Required by controller_manager === -->
  <ros2_control name="agilex_system" type="system">
    <hardware>
      
       Fortress namespace 
    
      <plugin>gz_ros2_control/GazeboSimSystem</plugin>
      <param name="position_proportional_gain">0.1</param>
      <param name="velocity_proportional_gain">100.0</param>
    </hardware>
    <joint name="front_left_wheel">
      <command_interface name="velocity"/>
      <state_interface name="velocity"/>
      <state_interface name="position"/>
      <param name="velocity_kp">100.0</param>
      <param name="velocity_ki">0.0</param>
      <param name="velocity_kd">0.0</param>
    </joint>
    <joint name="rear_left_wheel">
      <command_interface name="velocity"/>
      <state_interface name="velocity"/>
      <state_interface name="position"/>
      <param name="velocity_kp">100.0</param>
      <param name="velocity_ki">0.0</param>
      <param name="velocity_kd">0.0</param>
    </joint>
    <joint name="front_right_wheel">
      <command_interface name="velocity"/>
      <state_interface name="velocity"/>
      <state_interface name="position"/>
      <param name="velocity_kp">100.0</param>
      <param name="velocity_ki">0.0</param>
      <param name="velocity_kd">0.0</param>
    </joint>
    <joint name="rear_right_wheel">
      <command_interface name="velocity"/>
      <state_interface name="velocity"/>
      <state_interface name="position"/>
      <param name="velocity_kp">100.0</param>
      <param name="velocity_ki">0.0</param>
      <param name="velocity_kd">0.0</param>
    </joint>
  </ros2_control>

  <gazebo>
    <plugin filename="gz_ros2_control-system" name="gz_ros2_control::GazeboSimROS2ControlPlugin">
      <!-- <ros>
        <namespace>$(arg namespace)</namespace>   
      </ros> -->
      <!-- Path to the controller YAML   -->
      <parameters>
                /root/ros2_ws/install/share/ground_agent/config/agilex_diff_drive_controller.yaml
      </parameters>
    </plugin>
  </gazebo>

</robot>
