<?xml version="1.0" ?>
<!--
 ...........       ____  _ __
 |  ,-^-,  |      / __ )(_) /_______________ _____  ___
 | (  O  ) |     / __  / / __/ ___/ ___/ __ `/_  / / _ \
 | / ,..´  |    / /_/ / / /_/ /__/ /  / /_/ / / /_/  __/
    +.......   /_____/_/\__/\___/_/   \__,_/ /___/\___/

MIT License

Copyright (c) 2024 Bitcraze
-->

<sdf version="1.7">
  <model name="crazyflie">
    <link name="crazyflie/body">
      <pose> 0 0 17.425E-3 0 0 0</pose>
      <inertial>
        <mass>0.025</mass>
        <inertia>
          <ixx>16.571710E-06</ixx>
          <iyy>16.655602E-06</iyy>
          <izz>29.261652E-06</izz>
          <ixy>0.830806E-06</ixy>
          <ixz>0.718277E-06</ixz>
          <iyz>1.800197E-06</iyz>
        </inertia>
      </inertial>
      <collision name="crazyflie/body_collision">
        <geometry>
          <box>
            <size>0.10 0.10 34.850E-3</size>
          </box>
        </geometry>
      </collision>
      <visual name="crazyflie/body_visual">
        <geometry>
          <mesh>
            <uri>model://crazyflie/meshes/collada_files/cf2_assembly.dae</uri>
            <scale>5 5 5</scale>
          </mesh>
        </geometry>
      </visual>
      <sensor name='lidar' type='ray'>
        <pose>0 0 0.1 0 0 0</pose>
        <topic>lidar</topic>
        <update_rate>10</update_rate>
        <ray>
          <scan>
            <horizontal>
                <samples>4</samples>
                <resolution>1</resolution>
                <min_angle>-3.14</min_angle>
                <max_angle>1.57</max_angle>
            </horizontal>
            <vertical>
                <samples>1</samples>
                <resolution>0.01</resolution>
                <min_angle>0</min_angle>
                <max_angle>0</max_angle>
            </vertical>
          </scan>
          <range>
            <min>0.01</min>
            <max>3.49</max>
            <resolution>0.01</resolution>
          </range>
        </ray>
        <always_on>1</always_on>
        <visualize>true</visualize>
      </sensor>
    </link>
    <link name="crazyflie/m1_prop">
      <pose>0.031 -0.031 0.021 0 0 0</pose>
      <inertial>
        <mass>0.0008</mass>
        <inertia>
          <ixx>8.33333E-09</ixx>
          <iyy>1.08333E-07</iyy>
          <izz>1.13333E-07</izz>
        </inertia>
      </inertial>
      <visual name="crazyflie/m1_visual">
        <geometry>
          <mesh>
            <uri>model://crazyflie/meshes/collada_files/ccw_prop.dae</uri>
            <scale>5 5 5</scale>
          </mesh>
        </geometry>
      </visual>
    </link>
    <link name="crazyflie/m2_prop">
      <pose>-0.031 -0.031 0.021 0 0 0</pose>
      <inertial>
        <mass>0.0008</mass>
        <inertia>
          <ixx>8.33333E-09</ixx>
          <iyy>1.08333E-07</iyy>
          <izz>1.13333E-07</izz>
        </inertia>
      </inertial>
      <visual name="crazyflie/m2_visual">
        <geometry>
          <mesh>
            <uri>model://crazyflie/meshes/collada_files/cw_prop.dae</uri>
            <scale>5 5 5</scale>
          </mesh>
        </geometry>
      </visual>
    </link>
    <link name="crazyflie/m3_prop">
      <pose>-0.031 0.031 0.021 0 0 0</pose>
      <inertial>
        <mass>0.0008</mass>
        <inertia>
          <ixx>8.33333E-09</ixx>
          <iyy>1.08333E-07</iyy>
          <izz>1.13333E-07</izz>
        </inertia>
      </inertial>
      <visual name="crazyflie/m3_visual">
        <geometry>
          <mesh>
            <uri>model://crazyflie/meshes/collada_files/ccw_prop.dae</uri>
            <scale>5 5 5</scale>
          </mesh>
        </geometry>
      </visual>
    </link>
    <link name="crazyflie/m4_prop">
      <pose>0.031 0.031 0.021 0 0 0</pose>
      <inertial>
        <mass>0.0008</mass>
        <inertia>
          <ixx>8.33333E-09</ixx>
          <iyy>1.08333E-07</iyy>
          <izz>1.13333E-07</izz>
        </inertia>
      </inertial>
      <visual name="crazyflie/m4_visual">
        <geometry>
          <mesh>
            <uri>model://crazyflie/meshes/collada_files/cw_prop.dae</uri>
            <scale>5 5 5</scale>
          </mesh>
        </geometry>
      </visual>
    </link>
    <joint name="crazyflie/m1_joint" type="revolute">
      <child>crazyflie/m1_prop</child>
      <parent>crazyflie/body</parent>
      <axis>
        <xyz>0 0 1</xyz>
      </axis>
    </joint>
    <joint name="crazyflie/m2_joint" type="revolute">
      <child>crazyflie/m2_prop</child>
      <parent>crazyflie/body</parent>
      <axis>
        <xyz>0 0 1</xyz>
      </axis>
    </joint>
    <joint name="crazyflie/m3_joint" type="revolute">
      <child>crazyflie/m3_prop</child>
      <parent>crazyflie/body</parent>
      <axis>
        <xyz>0 0 1</xyz>
      </axis>
    </joint>
    <joint name="crazyflie/m4_joint" type="revolute">
      <child>crazyflie/m4_prop</child>
      <parent>crazyflie/body</parent>
      <axis>
        <xyz>0 0 1</xyz>
      </axis>
    </joint>

    <!-- VGA camera -->
    <model name="vga_camera">
         <!-- put the link just 1 cm below the deck -->
        <link name="vga_camera">
            <!-- x y  z    roll pitch  yaw  (m / rad)           -->
            <pose>0 0 -0.01  0 0 0</pose>      <!-- no rotation here -->

            <inertial>
                <mass>0.005</mass>
                <inertia>
                    <ixx>8.33e-06</ixx>
                    <ixy>0</ixy>
                    <ixz>0</ixz>
                    <iyy>8.33e-06</iyy>
                    <iyz>0</iyz>
                    <izz>8.33e-06</izz>
                </inertia>
            </inertial>
            <sensor name="down_cam" type="camera">
                <always_on>1</always_on>
                <pose>0 0 0  0 1.5708 0</pose>     <!-- pitch –90 ° (look straight down) -->
                <update_rate>60</update_rate>
                <visualize>true</visualize>
                <camera name="camera">
                    <horizontal_fov>1.0472</horizontal_fov>
                    <lens>
                        <intrinsics>
                            <!-- fx = fy = width / ( 2 * tan (hfov / 2 ) ) -->
                            <fx>554.3</fx>
                            <fy>554.3</fy>
                            <!-- cx = ( width + 1 ) / 2 -->
                            <cx>320.5</cx>
                            <!-- cy = ( height + 1 ) / 2 -->
                            <cy>240.5</cy>
                            <s>0</s>
                        </intrinsics>
                    </lens>
                    <image>
                        <width>640</width>
                        <height>480</height>
                        <format>R8G8B8</format>
                    </image>
                    <clip>
                        <near>0.08</near>       <!-- 8 cm: clips the hull, still sees ground -->
                        <far>50.0</far>
                    </clip>
                    <noise>
                        <type>gaussian</type>
                        <mean>0</mean>
                        <stddev>0.007</stddev>
                    </noise>
                </camera>
            </sensor>
        </link>
        <frame name="mount_point"/>
    </model>

    <joint name="vga_camera_joint" type="fixed">
      <parent>crazyflie/body</parent>
      <child>vga_camera</child>
    </joint>

    <plugin name="gas_sensor" filename="libgas_sensor.so">
      <emitter_topic>/hazards/toxic_gas/raw</emitter_topic>
      <sensor_topic>/crazyflie/gas/ppm</sensor_topic>
      <decay_length>10.0</decay_length>
    </plugin>

    <!-- plugins --> 
    <plugin
          filename="gz-sim-pose-publisher-system"
          name="gz::sim::systems::PosePublisher">
          <publish_link_pose>true</publish_link_pose>
          <publish_sensor_pose>true</publish_sensor_pose>
          <publish_collision_pose>false</publish_collision_pose>
          <publish_visual_pose>false</publish_visual_pose>
          <publish_nested_model_pose>true</publish_nested_model_pose>
          <publish_model_pose>false</publish_model_pose>
          <use_pose_vector_msg>true</use_pose_vector_msg>
          <static_publisher>true</static_publisher>
          <static_update_frequency>100</static_update_frequency>
      </plugin>
    <plugin
      filename="gz-sim-multicopter-motor-model-system"
      name="gz::sim::systems::MulticopterMotorModel">
      <robotNamespace>crazyflie</robotNamespace>
      <jointName>crazyflie/m1_joint</jointName>
      <linkName>crazyflie/m1_prop</linkName>
      <turningDirection>ccw</turningDirection>
      <maxRotVelocity>2618</maxRotVelocity>
      <motorConstant>1.28192e-08</motorConstant>
      <momentConstant>0.005964552</momentConstant>
      <rotorDragCoefficient>8.06428e-05</rotorDragCoefficient>
      <rollingMomentCoefficient>0.0000001</rollingMomentCoefficient>
      <rotorVelocitySlowdownSim>20</rotorVelocitySlowdownSim>
      <motorNumber>0</motorNumber>
      <motorType>velocity</motorType>
    </plugin>
    <plugin
      filename="gz-sim-multicopter-motor-model-system"
      name="gz::sim::systems::MulticopterMotorModel">
      <robotNamespace>crazyflie</robotNamespace>
      <jointName>crazyflie/m2_joint</jointName>
      <linkName>crazyflie/m2_prop</linkName>
      <turningDirection>cw</turningDirection>
      <maxRotVelocity>2618</maxRotVelocity>
      <motorConstant>1.28192e-08</motorConstant>
      <momentConstant>0.005964552</momentConstant>
      <rotorDragCoefficient>8.06428e-05</rotorDragCoefficient>
      <rollingMomentCoefficient>0.0000001</rollingMomentCoefficient>
      <rotorVelocitySlowdownSim>20</rotorVelocitySlowdownSim>
      <motorNumber>1</motorNumber>
      <motorType>velocity</motorType>
    </plugin>
    <plugin
      filename="gz-sim-multicopter-motor-model-system"
      name="gz::sim::systems::MulticopterMotorModel">
      <robotNamespace>crazyflie</robotNamespace>
      <jointName>crazyflie/m3_joint</jointName>
      <linkName>crazyflie/m3_prop</linkName>
      <turningDirection>ccw</turningDirection>
      <maxRotVelocity>2618</maxRotVelocity>
      <motorConstant>1.28192e-08</motorConstant>
      <momentConstant>0.005964552</momentConstant>
      <rotorDragCoefficient>8.06428e-05</rotorDragCoefficient>
      <rollingMomentCoefficient>0.0000001</rollingMomentCoefficient>
      <rotorVelocitySlowdownSim>20</rotorVelocitySlowdownSim>
      <motorNumber>2</motorNumber>
      <motorType>velocity</motorType>
    </plugin>
    <plugin
      filename="gz-sim-multicopter-motor-model-system"
      name="gz::sim::systems::MulticopterMotorModel">
      <robotNamespace>crazyflie</robotNamespace>
      <jointName>crazyflie/m4_joint</jointName>
      <linkName>crazyflie/m4_prop</linkName>
      <turningDirection>cw</turningDirection>
      <maxRotVelocity>2618</maxRotVelocity>
      <motorConstant>1.28192e-08</motorConstant>
      <momentConstant>0.005964552</momentConstant>
      <rotorDragCoefficient>8.06428e-05</rotorDragCoefficient>
      <rollingMomentCoefficient>0.0000001</rollingMomentCoefficient>
      <rotorVelocitySlowdownSim>20</rotorVelocitySlowdownSim>
      <motorNumber>3</motorNumber>
      <motorType>velocity</motorType>
    </plugin>
    <plugin
      filename="gz-sim-multicopter-control-system"
      name="gz::sim::systems::MulticopterVelocityControl">
      <robotNamespace>crazyflie</robotNamespace>
      <commandSubTopic>gazebo/command/twist</commandSubTopic>
      <enableSubTopic>enable</enableSubTopic>
      <comLinkName>crazyflie/body</comLinkName>
      <velocityGain>1.25 1.25 0.2425</velocityGain>
      <attitudeGain>0.02 0.02 0.02</attitudeGain>
      <angularRateGain>0.005 0.005 0.005</angularRateGain>
      <rotorConfiguration>
        <rotor>
          <jointName>crazyflie/m1_joint</jointName>
          <forceConstant>1.28192e-08</forceConstant>
          <momentConstant>0.005964552</momentConstant>
          <direction>1</direction>
        </rotor>
        <rotor>
          <jointName>crazyflie/m2_joint</jointName>
          <forceConstant>1.28192e-08</forceConstant>
          <momentConstant>0.005964552</momentConstant>
          <direction>-1</direction>
        </rotor>
        <rotor>
          <jointName>crazyflie/m3_joint</jointName>
          <forceConstant>1.28192e-08</forceConstant>
          <momentConstant>0.005964552</momentConstant>
          <direction>1</direction>
        </rotor>
        <rotor>
          <jointName>crazyflie/m4_joint</jointName>
          <forceConstant>1.28192e-08</forceConstant>
          <momentConstant>0.005964552</momentConstant>
          <direction>-1</direction>
        </rotor>
      </rotorConfiguration>
    </plugin>
    <plugin
      name="ignition::gazebo::systems::OdometryPublisher"
      filename="gz-sim-odometry-publisher-system">
      <odom_frame>crazyflie/odom</odom_frame>
      <robot_base_frame>crazyflie::body</robot_base_frame>
      <dimensions>3</dimensions>
    </plugin>

  </model>
</sdf>